Workbook

Sheet 요약
A1: Profit Calculator 1.0.1 · 3×6 수익성 비교
A2: 생성 시각 | B2: 2026-08-23 21:42:44 | D2: 분석 기준 | E2: 3개 공간 × 6개 작물 = 18개 대안 시나리오
A4: 시나리오ID | B4: 사업장ID | C4: 사업장명 | D4: 작물 | E4: 공실 전체면적(m²) | F4: 사용가능 바닥면적(m²) | G4: 재배면적(m²) | H4: 원하는 월세(원) | I4: 월 총생산량(kg) | J4: 월 판매량(kg) | K4: 월 매출(원) | L4: 월평균 전력량(kWh) | M4: 월 전기비(원) | N4: 배액률 | O4: 월 작물 순소비량(m³) | P4: 월 배액량(m³) | Q4: 월 기타 용수량(m³) | R4: 월 총 용수량(m³) | S4: 월 수도비(원) | T4: 월 재료비(원) | U4: 월 인건비(원) | V4: 월 기기 대여비(원) | W4: 기타비용(원) | X4: 월 운영비(원) | Y4: 월 영업이익(원) | Z4: 공간 대여자 배분율 | AA4: 공간 대여자 예상수익(원) | AB4: 공실 월세 대비 차이(원) | AC4: 사업장 영업이익(원) | AD4: 추천 방식 | AE4: 계약 형태
A5: S001-상추 | B5: S001 | C5: 부산 금정구 농장 | D5: 상추 | E5: 164 | F5: 106.6 | G5: 426.4 | H5: 1200000 | I5: 1279.2 | J5: 1151.28 | K5: 9210240 | L5: 35787.467 | M5: 5547057.4 | N5: 0.3 | O5: 41.502933 | P5: 17.786971 | Q5: 0.99766667 | R5: 60.287571 | S5: 138661.41 | T5: 3317798.1 | U5: 6600672 | V5: 2345200 | W5: 300000 | X5: 18249389 | Y5: -9039148.9 | Z5: 0.8 | AA5: -7231319.1 | AB5: -8431319.1 | AC5: -1807829.8 | AD5: 개인취미 대여 방식 추천 | AE5: 단기계약형
A6: S001-딸기 | B6: S001 | C6: 부산 금정구 농장 | D6: 딸기 | E6: 164 | F6: 106.6 | G6: 213.2 | H6: 1200000 | I6: 426.4 | J6: 383.76 | K6: 11512800 | L6: 12923.461 | M6: 2003136.5 | N6: 0.3 | O6: 5.83635 | P6: 2.5012929 | Q6: 0.99766667 | R6: 9.3353095 | S6: 21471.212 | T6: 966252.86 | U6: 2200224 | V6: 2345200 | W6: 300000 | X6: 7836284.5 | Y6: 3676515.5 | Z6: 0.8 | AA6: 2941212.4 | AB6: 1741212.4 | AC6: 735303.09 | AD6: 도심형 대량생산 스마트팜 방식 추천 | AE6: 장기계약형
A7: S001-바질 | B7: S001 | C7: 부산 금정구 농장 | D7: 바질 | E7: 164 | F7: 106.6 | G7: 319.8 | H7: 1200000 | I7: 767.52 | J7: 690.768 | K7: 17269200 | L7: 20332.354 | M7: 3151514.8 | N7: 0.3 | O7: 10.699975 | P7: 4.5857036 | Q7: 0.99766667 | R7: 16.283345 | S7: 37451.694 | T7: 1904713.6 | U7: 3960403.2 | V7: 2345200 | W7: 300000 | X7: 11699283 | Y7: 5569916.7 | Z7: 0.8 | AA7: 4455933.4 | AB7: 3255933.4 | AC7: 1113983.3 | AD7: 도심형 대량생산 스마트팜 방식 추천 | AE7: 장기계약형
A8: S001-애플민트 | B8: S001 | C8: 부산 금정구 농장 | D8: 애플민트 | E8: 164 | F8: 106.6 | G8: 426.4 | H8: 1200000 | I8: 579.904 | J8: 521.9136 | K8: 31314816 | L8: 24496.31 | M8: 3796928 | N8: 0.3 | O8: 28.533267 | P8: 12.228543 | Q8: 0.99766667 | R8: 41.759476 | S8: 96046.795 | T8: 1668036.2 | U8: 2992304.6 | V8: 2345200 | W8: 300000 | X8: 11198516 | Y8: 20116300 | Z8: 0.8 | AA8: 16093040 | AB8: 14893040 | AC8: 4023260.1 | AD8: 도심형 대량생산 스마트팜 방식 추천 | AE8: 장기계약형
A9: S001-쪽파 | B9: S001 | C9: 부산 금정구 농장 | D9: 쪽파 | E9: 164 | F9: 106.6 | G9: 319.8 | H9: 1200000 | I9: 639.6 | J9: 575.64 | K9: 5756400 | L9: 26622.106 | M9: 4126426.4 | N9: 0.3 | O9: 29.18175 | P9: 12.506464 | Q9: 0.99766667 | R9: 42.685881 | S9: 98177.526 | T9: 1057624.3 | U9: 3300336 | V9: 2345200 | W9: 300000 | X9: 11227764 | Y9: -5471364.2 | Z9: 0.8 | AA9: -4377091.3 | AB9: -5577091.3 | AC9: -1094272.8 | AD9: 개인취미 대여 방식 추천 | AE9: 단기계약형
A10: S001-병풀 | B10: S001 | C10: 부산 금정구 농장 | D10: 병풀 | E10: 164 | F10: 106.6 | G10: 319.8 | H10: 1200000 | I10: 639.6 | J10: 575.64 | K10: 11512800 | L10: 23610.914 | M10: 3659691.7 | N10: 0.3 | O10: 29.18175 | P10: 12.506464 | Q10: 0.99766667 | R10: 42.685881 | S10: 98177.526 | T10: 1366765.4 | U10: 3300336 | V10: 2345200 | W10: 300000 | X10: 11070171 | Y10: 442629.44 | Z10: 0.8 | AA10: 354103.55 | AB10: -845896.45 | AC10: 88525.888 | AD10: 개인취미 대여 방식 추천 | AE10: 단기계약형
A11: S002-상추 | B11: S002 | C11: 부산 해운대 농장 | D11: 상추 | E11: 66 | F11: 42.9 | G11: 171.6 | H11: 800000 | I11: 514.8 | J11: 463.32 | K11: 3706560 | L11: 14408.112 | M11: 2233257.4 | N11: 0.3 | O11: 16.7024 | P11: 7.1581714 | Q11: 0.4015 | R11: 24.262071 | S11: 55802.764 | T11: 1335211.4 | U11: 2656368 | V11: 943800 | W11: 300000 | X11: 7524439.6 | Y11: -3817879.6 | Z11: 0.8 | AA11: -3054303.7 | AB11: -3854303.7 | AC11: -763575.92 | AD11: 개인취미 대여 방식 추천 | AE11: 단기계약형
A12: S002-딸기 | B12: S002 | C12: 부산 해운대 농장 | D12: 딸기 | E12: 66 | F12: 42.9 | G12: 85.8 | H12: 800000 | I12: 171.6 | J12: 154.44 | K12: 4633200 | L12: 5205.229 | M12: 806810.49 | N12: 0.3 | O12: 2.348775 | P12: 1.0066179 | Q12: 0.4015 | R12: 3.7568929 | S12: 8640.8536 | T12: 388857.86 | U12: 885456 | V12: 943800 | W12: 300000 | X12: 3333565.2 | Y12: 1299634.8 | Z12: 0.8 | AA12: 1039707.8 | AB12: 239707.84 | AC12: 259926.96 | AD12: 도심형 대량생산 스마트팜 방식 추천 | AE12: 장기계약형
A13: S002-바질 | B13: S002 | C13: 부산 해운대 농장 | D13: 바질 | E13: 66 | F13: 42.9 | G13: 128.7 | H13: 800000 | I13: 308.88 | J13: 277.992 | K13: 6949800 | L13: 8186.5214 | M13: 1268910.8 | N13: 0.3 | O13: 4.3060875 | P13: 1.8454661 | Q13: 0.4015 | R13: 6.5530536 | S13: 15072.023 | T13: 766531.07 | U13: 1593820.8 | V13: 943800 | W13: 300000 | X13: 4888134.7 | Y13: 2061665.3 | Z13: 0.8 | AA13: 1649332.2 | AB13: 849332.24 | AC13: 412333.06 | AD13: 도심형 대량생산 스마트팜 방식 추천 | AE13: 장기계약형
A14: S002-애플민트 | B14: S002 | C14: 부산 해운대 농장 | D14: 애플민트 | E14: 66 | F14: 42.9 | G14: 171.6 | H14: 800000 | I14: 233.376 | J14: 210.0384 | K14: 12602304 | L14: 9869.2835 | M14: 1529738.9 | N14: 0.3 | O14: 11.4829 | P14: 4.9212429 | Q14: 0.4015 | R14: 16.805643 | S14: 38652.979 | T14: 671282.86 | U14: 1204220.2 | V14: 943800 | W14: 300000 | X14: 4687694.9 | Y14: 7914609.1 | Z14: 0.8 | AA14: 6331687.2 | AB14: 5531687.2 | AC14: 1582921.8 | AD14: 도심형 대량생산 스마트팜 방식 추천 | AE14: 장기계약형
A15: S002-쪽파 | B15: S002 | C15: 부산 해운대 농장 | D15: 쪽파 | E15: 66 | F15: 42.9 | G15: 128.7 | H15: 800000 | I15: 257.4 | J15: 231.66 | K15: 2316600 | L15: 10718.098 | M15: 1661305.2 | N15: 0.3 | O15: 11.743875 | P15: 5.0330893 | Q15: 0.4015 | R15: 17.178464 | S15: 39510.468 | T15: 425629.29 | U15: 1328184 | V15: 943800 | W15: 300000 | X15: 4698429 | Y15: -2381829 | Z15: 0.8 | AA15: -1905463.2 | AB15: -2705463.2 | AC15: -476365.79 | AD15: 개인취미 대여 방식 추천 | AE15: 단기계약형
A16: S002-병풀 | B16: S002 | C16: 부산 해운대 농장 | D16: 병풀 | E16: 66 | F16: 42.9 | G16: 128.7 | H16: 800000 | I16: 257.4 | J16: 231.66 | K16: 4633200 | L16: 9514.1449 | M16: 1474692.5 | N16: 0.3 | O16: 11.743875 | P16: 5.0330893 | Q16: 0.4015 | R16: 17.178464 | S16: 39510.468 | T16: 550039.71 | U16: 1328184 | V16: 943800 | W16: 300000 | X16: 4636226.6 | Y16: -3026.6473 | Z16: 0.8 | AA16: -2421.3179 | AB16: -802421.32 | AC16: -605.32947 | AD16: 개인취미 대여 방식 추천 | AE16: 단기계약형
... A22: S003-병풀 | B22: S003 | C22: 부산 사하구 농장 | D22: 병풀 | E22: 324 | F22: 210.6 | G22: 631.8 | H22: 3500000 | I22: 1263.6 | J22: 1137.24 | K22: 22744800 | L22: 46615.988 | M22: 7225478.2 | N22: 0.3 | O22: 57.65175 | P22: 24.707893 | Q22: 1.971 | R22: 84.330643 | S22: 193960.48 | T22: 2700195 | U22: 6520176 | V22: 4633200 | W22: 300000 | X22: 21573010 | Y22: 1171790.3 | Z22: 0.8 | AA22: 937432.28 | AB22: -2562567.7 | AC22: 234358.07 | AD22: 개인취미 대여 방식 추천 | AE22: 단기계약형

Sheet 비용구성
A1: 시나리오별 월 비용 구성 및 운영비 대비 비율
A2: 비율 기준 | B2: 각 비용 ÷ 월 운영비 | D2: 기기 대여비 기준 | E2: 사용가능 바닥면적 × 22,000원/m²/month
A4: 시나리오ID | B4: 사업장 | C4: 작물 | D4: 월 운영비(원) | E4: 전기비(원) | F4: 전기비 비율 | G4: 수도비(원) | H4: 수도비 비율 | I4: 재료비(원) | J4: 재료비 비율 | K4: 인건비(원) | L4: 인건비 비율 | M4: 기기 대여비(원) | N4: 기기 대여비 비율 | O4: 기타비용(원) | P4: 기타비용 비율 | Q4: 비용 비율 합계
A5: S001-상추 | B5: 부산 금정구 농장 | C5: 상추 | D5: 18249389 | E5: 5547057.4 | F5: =IF($D5=0,0,E5/$D5) | G5: 138661.41 | H5: =IF($D5=0,0,G5/$D5) | I5: 3317798.1 | J5: =IF($D5=0,0,I5/$D5) | K5: 6600672 | L5: =IF($D5=0,0,K5/$D5) | M5: 2345200 | N5: =IF($D5=0,0,M5/$D5) | O5: 300000 | P5: =IF($D5=0,0,O5/$D5) | Q5: =SUM(F5,H5,J5,L5,N5,P5)
A6: S001-딸기 | B6: 부산 금정구 농장 | C6: 딸기 | D6: 7836284.5 | E6: 2003136.5 | F6: =IF($D6=0,0,E6/$D6) | G6: 21471.212 | H6: =IF($D6=0,0,G6/$D6) | I6: 966252.86 | J6: =IF($D6=0,0,I6/$D6) | K6: 2200224 | L6: =IF($D6=0,0,K6/$D6) | M6: 2345200 | N6: =IF($D6=0,0,M6/$D6) | O6: 300000 | P6: =IF($D6=0,0,O6/$D6) | Q6: =SUM(F6,H6,J6,L6,N6,P6)
A7: S001-바질 | B7: 부산 금정구 농장 | C7: 바질 | D7: 11699283 | E7: 3151514.8 | F7: =IF($D7=0,0,E7/$D7) | G7: 37451.694 | H7: =IF($D7=0,0,G7/$D7) | I7: 1904713.6 | J7: =IF($D7=0,0,I7/$D7) | K7: 3960403.2 | L7: =IF($D7=0,0,K7/$D7) | M7: 2345200 | N7: =IF($D7=0,0,M7/$D7) | O7: 300000 | P7: =IF($D7=0,0,O7/$D7) | Q7: =SUM(F7,H7,J7,L7,N7,P7)
A8: S001-애플민트 | B8: 부산 금정구 농장 | C8: 애플민트 | D8: 11198516 | E8: 3796928 | F8: =IF($D8=0,0,E8/$D8) | G8: 96046.795 | H8: =IF($D8=0,0,G8/$D8) | I8: 1668036.2 | J8: =IF($D8=0,0,I8/$D8) | K8: 2992304.6 | L8: =IF($D8=0,0,K8/$D8) | M8: 2345200 | N8: =IF($D8=0,0,M8/$D8) | O8: 300000 | P8: =IF($D8=0,0,O8/$D8) | Q8: =SUM(F8,H8,J8,L8,N8,P8)
A9: S001-쪽파 | B9: 부산 금정구 농장 | C9: 쪽파 | D9: 11227764 | E9: 4126426.4 | F9: =IF($D9=0,0,E9/$D9) | G9: 98177.526 | H9: =IF($D9=0,0,G9/$D9) | I9: 1057624.3 | J9: =IF($D9=0,0,I9/$D9) | K9: 3300336 | L9: =IF($D9=0,0,K9/$D9) | M9: 2345200 | N9: =IF($D9=0,0,M9/$D9) | O9: 300000 | P9: =IF($D9=0,0,O9/$D9) | Q9: =SUM(F9,H9,J9,L9,N9,P9)
A10: S001-병풀 | B10: 부산 금정구 농장 | C10: 병풀 | D10: 11070171 | E10: 3659691.7 | F10: =IF($D10=0,0,E10/$D10) | G10: 98177.526 | H10: =IF($D10=0,0,G10/$D10) | I10: 1366765.4 | J10: =IF($D10=0,0,I10/$D10) | K10: 3300336 | L10: =IF($D10=0,0,K10/$D10) | M10: 2345200 | N10: =IF($D10=0,0,M10/$D10) | O10: 300000 | P10: =IF($D10=0,0,O10/$D10) | Q10: =SUM(F10,H10,J10,L10,N10,P10)
A11: S002-상추 | B11: 부산 해운대 농장 | C11: 상추 | D11: 7524439.6 | E11: 2233257.4 | F11: =IF($D11=0,0,E11/$D11) | G11: 55802.764 | H11: =IF($D11=0,0,G11/$D11) | I11: 1335211.4 | J11: =IF($D11=0,0,I11/$D11) | K11: 2656368 | L11: =IF($D11=0,0,K11/$D11) | M11: 943800 | N11: =IF($D11=0,0,M11/$D11) | O11: 300000 | P11: =IF($D11=0,0,O11/$D11) | Q11: =SUM(F11,H11,J11,L11,N11,P11)
A12: S002-딸기 | B12: 부산 해운대 농장 | C12: 딸기 | D12: 3333565.2 | E12: 806810.49 | F12: =IF($D12=0,0,E12/$D12) | G12: 8640.8536 | H12: =IF($D12=0,0,G12/$D12) | I12: 388857.86 | J12: =IF($D12=0,0,I12/$D12) | K12: 885456 | L12: =IF($D12=0,0,K12/$D12) | M12: 943800 | N12: =IF($D12=0,0,M12/$D12) | O12: 300000 | P12: =IF($D12=0,0,O12/$D12) | Q12: =SUM(F12,H12,J12,L12,N12,P12)
A13: S002-바질 | B13: 부산 해운대 농장 | C13: 바질 | D13: 4888134.7 | E13: 1268910.8 | F13: =IF($D13=0,0,E13/$D13) | G13: 15072.023 | H13: =IF($D13=0,0,G13/$D13) | I13: 766531.07 | J13: =IF($D13=0,0,I13/$D13) | K13: 1593820.8 | L13: =IF($D13=0,0,K13/$D13) | M13: 943800 | N13: =IF($D13=0,0,M13/$D13) | O13: 300000 | P13: =IF($D13=0,0,O13/$D13) | Q13: =SUM(F13,H13,J13,L13,N13,P13)
A14: S002-애플민트 | B14: 부산 해운대 농장 | C14: 애플민트 | D14: 4687694.9 | E14: 1529738.9 | F14: =IF($D14=0,0,E14/$D14) | G14: 38652.979 | H14: =IF($D14=0,0,G14/$D14) | I14: 671282.86 | J14: =IF($D14=0,0,I14/$D14) | K14: 1204220.2 | L14: =IF($D14=0,0,K14/$D14) | M14: 943800 | N14: =IF($D14=0,0,M14/$D14) | O14: 300000 | P14: =IF($D14=0,0,O14/$D14) | Q14: =SUM(F14,H14,J14,L14,N14,P14)
A15: S002-쪽파 | B15: 부산 해운대 농장 | C15: 쪽파 | D15: 4698429 | E15: 1661305.2 | F15: =IF($D15=0,0,E15/$D15) | G15: 39510.468 | H15: =IF($D15=0,0,G15/$D15) | I15: 425629.29 | J15: =IF($D15=0,0,I15/$D15) | K15: 1328184 | L15: =IF($D15=0,0,K15/$D15) | M15: 943800 | N15: =IF($D15=0,0,M15/$D15) | O15: 300000 | P15: =IF($D15=0,0,O15/$D15) | Q15: =SUM(F15,H15,J15,L15,N15,P15)
A16: S002-병풀 | B16: 부산 해운대 농장 | C16: 병풀 | D16: 4636226.6 | E16: 1474692.5 | F16: =IF($D16=0,0,E16/$D16) | G16: 39510.468 | H16: =IF($D16=0,0,G16/$D16) | I16: 550039.71 | J16: =IF($D16=0,0,I16/$D16) | K16: 1328184 | L16: =IF($D16=0,0,K16/$D16) | M16: 943800 | N16: =IF($D16=0,0,M16/$D16) | O16: 300000 | P16: =IF($D16=0,0,O16/$D16) | Q16: =SUM(F16,H16,J16,L16,N16,P16)
... A22: S003-병풀 | B22: 부산 사하구 농장 | C22: 병풀 | D22: 21573010 | E22: 7225478.2 | F22: =IF($D22=0,0,E22/$D22) | G22: 193960.48 | H22: =IF($D22=0,0,G22/$D22) | I22: 2700195 | J22: =IF($D22=0,0,I22/$D22) | K22: 6520176 | L22: =IF($D22=0,0,K22/$D22) | M22: 4633200 | N22: =IF($D22=0,0,M22/$D22) | O22: 300000 | P22: =IF($D22=0,0,O22/$D22) | Q22: =SUM(F22,H22,J22,L22,N22,P22)

Sheet 계산상세
A1: 계산 블록 1~10 상세 결과
A3: 시나리오ID | B3: 사업장 | C3: 작물 | D3: 계산 블록 | E3: 항목 | F3: 값 | G3: 단위
A4: S001-상추 | B4: 부산 금정구 농장 | C4: 상추 | D4: 1. 공간 | E4: 공실 전체면적 | F4: 164 | G4: m²
A5: S001-상추 | B5: 부산 금정구 농장 | C5: 상추 | D5: 1. 공간 | E5: 사용가능 바닥면적 | F5: 106.6 | G5: m²
A6: S001-상추 | B6: 부산 금정구 농장 | C6: 상추 | D6: 1. 공간 | E6: 작물별 모듈 층 수 | F6: 4 | G6: 층
A7: S001-상추 | B7: 부산 금정구 농장 | C7: 상추 | D7: 1. 공간 | E7: 재배면적 | F7: 426.4 | G7: m²
A8: S001-상추 | B8: 부산 금정구 농장 | C8: 상추 | D8: 1. 공간 | E8: 공간 체적 | F8: 410 | G8: m³
A9: S001-상추 | B9: 부산 금정구 농장 | C9: 상추 | D9: 2. 생산 | E9: 월 총생산량 | F9: 1279.2 | G9: kg
A10: S001-상추 | B10: 부산 금정구 농장 | C10: 상추 | D10: 2. 생산 | E10: 월 판매량 | F10: 1151.28 | G10: kg
A11: S001-상추 | B11: 부산 금정구 농장 | C11: 상추 | D11: 3. 매출 | E11: 판매가격 | F11: 8000 | G11: 원/kg
A12: S001-상추 | B12: 부산 금정구 농장 | C12: 상추 | D12: 3. 매출 | E12: 월 매출 | F12: 9210240 | G12: 원
A13: S001-상추 | B13: 부산 금정구 농장 | C13: 상추 | D13: 4. 조명·냉난방 | E13: 필요 조명전력 | F13: 30457.143 | G13: W
A14: S001-상추 | B14: 부산 금정구 농장 | C14: 상추 | D14: 4. 조명·냉난방 | E14: 월 조명전력량 | F14: 13896.071 | G14: kWh
A15: S001-상추 | B15: 부산 금정구 농장 | C15: 상추 | D15: 5. 습도 | E15: 월 증발산량 | F15: 41502.933 | G15: kg
... A669: S003-병풀 | B669: 부산 사하구 농장 | C669: 병풀 | D669: 10. 수익 | E669: 사업장 영업이익 | F669: 234358.07 | G669: 원

Sheet 월별전력량
A1: 12개월 환경제어 전력량
A3: 시나리오ID | B3: 사업장 | C3: 작물 | D3: 월 | E3: 외기온도(°C) | F3: 외기상대습도 | G3: 조명(kWh) | H3: 난방(kWh) | I3: 냉방(kWh) | J3: 제습(kWh) | K3: 가습(kWh) | L3: 총합(kWh)
A4: S001-상추 | B4: 부산 금정구 농장 | C4: 상추 | D4: 1월 | E4: -2 | F4: 0.55 | G4: 13896.071 | H4: 141.62431 | I4: 4085.7019 | J4: 17549.949 | K4: 0 | L4: 35673.346
A5: S001-상추 | B5: 부산 금정구 농장 | C5: 상추 | D5: 2월 | E5: 1 | F5: 0.52 | G5: 13896.071 | H5: 122.31191 | I5: 4128.6184 | J5: 17528.387 | K5: 0 | L5: 35675.389
A6: S001-상추 | B6: 부산 금정구 농장 | C6: 상추 | D6: 3월 | E6: 7 | F6: 0.55 | G6: 13896.071 | H6: 83.687093 | I6: 4214.4513 | J6: 17500.293 | K6: 0 | L6: 35694.503
A7: S001-상추 | B7: 부산 금정구 농장 | C7: 상추 | D7: 4월 | E7: 14 | F7: 0.58 | G7: 13896.071 | H7: 38.624812 | I7: 4314.5897 | J7: 17484.518 | K7: 0 | L7: 35733.804
A8: S001-상추 | B8: 부산 금정구 농장 | C8: 상추 | D8: 5월 | E8: 19 | F8: 0.65 | G8: 13896.071 | H8: 6.4374687 | I8: 4386.1171 | J8: 17504.28 | K8: 0 | L8: 35792.906
A9: S001-상추 | B9: 부산 금정구 농장 | C9: 상추 | D9: 6월 | E9: 23 | F9: 0.72 | G9: 13896.071 | H9: 0 | I9: 4469.089 | J9: 17526.354 | K9: 0 | L9: 35891.515
A10: S001-상추 | B10: 부산 금정구 농장 | C10: 상추 | D10: 7월 | E10: 26 | F10: 0.78 | G10: 13896.071 | H10: 0 | I10: 4537.7553 | J10: 17557.841 | K10: 0 | L10: 35991.668
A11: S001-상추 | B11: 부산 금정구 농장 | C11: 상추 | D11: 8월 | E11: 27 | F11: 0.76 | G11: 13896.071 | H11: 0 | I11: 4560.6441 | J11: 17552.644 | K11: 0 | L11: 36009.36
A12: S001-상추 | B12: 부산 금정구 농장 | C12: 상추 | D12: 9월 | E12: 22 | F12: 0.7 | G12: 13896.071 | H12: 0 | I12: 4446.2002 | J12: 17519.353 | K12: 0 | L12: 35861.625
A13: S001-상추 | B13: 부산 금정구 농장 | C13: 상추 | D13: 10월 | E13: 15 | F13: 0.62 | G13: 13896.071 | H13: 32.187344 | I13: 4328.8952 | J13: 17492.936 | K13: 0 | L13: 35750.09
A14: S001-상추 | B14: 부산 금정구 농장 | C14: 상추 | D14: 11월 | E14: 7 | F14: 0.58 | G14: 13896.071 | H14: 83.687093 | I14: 4214.4513 | J14: 17504.707 | K14: 0 | L14: 35698.917
A15: S001-상추 | B15: 부산 금정구 농장 | C15: 상추 | D15: 12월 | E15: 0 | F15: 0.55 | G15: 13896.071 | H15: 128.74937 | I15: 4114.3129 | J15: 17537.348 | K15: 0 | L15: 35676.481
... A219: S003-병풀 | B219: 부산 사하구 농장 | C219: 병풀 | D219: 12월 | E219: 0 | F219: 0.55 | G219: 16471.929 | H219: 311.04967 | I219: 4801.3778 | J219: 24870.402 | K219: 0 | L219: 46454.758

Sheet 입력기준
A1: 모델 기준 및 입력 파일
A3: 구분 | B3: 항목 | C3: 값 | D3: 설명
A4: 버전 | B4: 프로그램 버전 | C4: 1.0.1 | D4: 6개 작물 비교 및 현실화한 비용 산정 반영
A5: 시나리오 | B5: 조합 방식 | C5: 공간 × 작물 | D5: 모든 공간에 모든 작물을 각각 적용
A6: 공간 | B6: 재배가능 비율 | C6: 0.65 | D6: space_info.csv 입력; 현재 모든 공간에 동일 적용
A7: 비용 | B7: 면적당 월 기기 대여비 | C7: 22,000 원/m²/month | D7: 사용가능 바닥면적 기준
A8: 비용 | B8: 월 기타비용 | C8: 300,000 원/month | D8: standard_info.csv 공통값; 모든 시나리오에 월 1회 적용
A9: 수도 | B9: 배액률 | C9: 30% | D9: standard_info.csv 공통값; 모든 작물에 동일 적용
A10: 수도 | B10: 수도 종합단가 | C10: 2,300 원/m³ | D10: standard_info.csv 입력
A11: 수익 | B11: 공간 대여자 배분비율 | C11: 0.8 | D11: contraction_info.csv 입력
A12: 재료비 | B12: 모종비 적용 기준 | C12: 기존 1회 단가의 1/3을 매월 적용 | D12: 기존 단가로 연 4회 구입하는 것과 같은 연간 비용
A13: 재료비 | B13: 양액 단가 | C13: 20 원/L | D13: standard_info.csv 입력
A14: 재료비 | B14: 양액량 기준 | C14: 배액 포함 월 작물 관수량 | D14: water_result의 monthly_crop_irrigation_l 재사용; 기타 용수 제외
... A21: 주의 | B21: 18개 결과 합산 | C21: 비교용 | D21: 같은 공간의 대안 작물을 동시에 운영한 합계가 아님

Sheet 검증
A1: 계산 결과 검증
A2: MODEL STATUS | B2: =IF(COUNTIF(G5:G58,"FAIL")=0,"PASS","FAIL")
A4: 시나리오ID | B4: 검증 항목 | C4: 실제값 | D4: 기대값 | E4: 차이 | F4: 허용오차 | G4: 상태
A5: S001-상추 | B5: 월 영업이익 = 공간 대여자 예상수익 + 사업장 영업이익 | C5: ='요약'!Y5 | D5: ='요약'!AA5+'요약'!AC5 | E5: =C5-D5 | F5: 0.5 | G5: =IF(ABS(E5)<=F5,"PASS","FAIL")
A6: S001-상추 | B6: 월 총 용수량 = 작물 순소비량 + 배액량 + 기타 용수량 | C6: ='요약'!R5 | D6: ='요약'!O5+'요약'!P5+'요약'!Q5 | E6: =C6-D6 | F6: 0.001 | G6: =IF(ABS(E6)<=F6,"PASS","FAIL")
A7: S001-상추 | B7: 월 운영비 = 전기비 + 수도비 + 재료비 + 인건비 + 기기 대여비 + 기타비용 | C7: ='비용구성'!D5 | D7: ='비용구성'!E5+'비용구성'!G5+'비용구성'!I5+'비용구성'!K5+'비용구성'!M5+'비용구성'!O5 | E7: =C7-D7 | F7: 0.5 | G7: =IF(ABS(E7)<=F7,"PASS","FAIL")
A8: S001-딸기 | B8: 월 영업이익 = 공간 대여자 예상수익 + 사업장 영업이익 | C8: ='요약'!Y6 | D8: ='요약'!AA6+'요약'!AC6 | E8: =C8-D8 | F8: 0.5 | G8: =IF(ABS(E8)<=F8,"PASS","FAIL")
A9: S001-딸기 | B9: 월 총 용수량 = 작물 순소비량 + 배액량 + 기타 용수량 | C9: ='요약'!R6 | D9: ='요약'!O6+'요약'!P6+'요약'!Q6 | E9: =C9-D9 | F9: 0.001 | G9: =IF(ABS(E9)<=F9,"PASS","FAIL")
A10: S001-딸기 | B10: 월 운영비 = 전기비 + 수도비 + 재료비 + 인건비 + 기기 대여비 + 기타비용 | C10: ='비용구성'!D6 | D10: ='비용구성'!E6+'비용구성'!G6+'비용구성'!I6+'비용구성'!K6+'비용구성'!M6+'비용구성'!O6 | E10: =C10-D10 | F10: 0.5 | G10: =IF(ABS(E10)<=F10,"PASS","FAIL")
A11: S001-바질 | B11: 월 영업이익 = 공간 대여자 예상수익 + 사업장 영업이익 | C11: ='요약'!Y7 | D11: ='요약'!AA7+'요약'!AC7 | E11: =C11-D11 | F11: 0.5 | G11: =IF(ABS(E11)<=F11,"PASS","FAIL")
A12: S001-바질 | B12: 월 총 용수량 = 작물 순소비량 + 배액량 + 기타 용수량 | C12: ='요약'!R7 | D12: ='요약'!O7+'요약'!P7+'요약'!Q7 | E12: =C12-D12 | F12: 0.001 | G12: =IF(ABS(E12)<=F12,"PASS","FAIL")
A13: S001-바질 | B13: 월 운영비 = 전기비 + 수도비 + 재료비 + 인건비 + 기기 대여비 + 기타비용 | C13: ='비용구성'!D7 | D13: ='비용구성'!E7+'비용구성'!G7+'비용구성'!I7+'비용구성'!K7+'비용구성'!M7+'비용구성'!O7 | E13: =C13-D13 | F13: 0.5 | G13: =IF(ABS(E13)<=F13,"PASS","FAIL")
A14: S001-애플민트 | B14: 월 영업이익 = 공간 대여자 예상수익 + 사업장 영업이익 | C14: ='요약'!Y8 | D14: ='요약'!AA8+'요약'!AC8 | E14: =C14-D14 | F14: 0.5 | G14: =IF(ABS(E14)<=F14,"PASS","FAIL")
A15: S001-애플민트 | B15: 월 총 용수량 = 작물 순소비량 + 배액량 + 기타 용수량 | C15: ='요약'!R8 | D15: ='요약'!O8+'요약'!P8+'요약'!Q8 | E15: =C15-D15 | F15: 0.001 | G15: =IF(ABS(E15)<=F15,"PASS","FAIL")
A16: S001-애플민트 | B16: 월 운영비 = 전기비 + 수도비 + 재료비 + 인건비 + 기기 대여비 + 기타비용 | C16: ='비용구성'!D8 | D16: ='비용구성'!E8+'비용구성'!G8+'비용구성'!I8+'비용구성'!K8+'비용구성'!M8+'비용구성'!O8 | E16: =C16-D16 | F16: 0.5 | G16: =IF(ABS(E16)<=F16,"PASS","FAIL")
A17: S001-쪽파 | B17: 월 영업이익 = 공간 대여자 예상수익 + 사업장 영업이익 | C17: ='요약'!Y9 | D17: ='요약'!AA9+'요약'!AC9 | E17: =C17-D17 | F17: 0.5 | G17: =IF(ABS(E17)<=F17,"PASS","FAIL")
A18: S001-쪽파 | B18: 월 총 용수량 = 작물 순소비량 + 배액량 + 기타 용수량 | C18: ='요약'!R9 | D18: ='요약'!O9+'요약'!P9+'요약'!Q9 | E18: =C18-D18 | F18: 0.001 | G18: =IF(ABS(E18)<=F18,"PASS","FAIL")
A19: S001-쪽파 | B19: 월 운영비 = 전기비 + 수도비 + 재료비 + 인건비 + 기기 대여비 + 기타비용 | C19: ='비용구성'!D9 | D19: ='비용구성'!E9+'비용구성'!G9+'비용구성'!I9+'비용구성'!K9+'비용구성'!M9+'비용구성'!O9 | E19: =C19-D19 | F19: 0.5 | G19: =IF(ABS(E19)<=F19,"PASS","FAIL")
A20: S001-병풀 | B20: 월 영업이익 = 공간 대여자 예상수익 + 사업장 영업이익 | C20: ='요약'!Y10 | D20: ='요약'!AA10+'요약'!AC10 | E20: =C20-D20 | F20: 0.5 | G20: =IF(ABS(E20)<=F20,"PASS","FAIL")
A21: S001-병풀 | B21: 월 총 용수량 = 작물 순소비량 + 배액량 + 기타 용수량 | C21: ='요약'!R10 | D21: ='요약'!O10+'요약'!P10+'요약'!Q10 | E21: =C21-D21 | F21: 0.001 | G21: =IF(ABS(E21)<=F21,"PASS","FAIL")
A22: S001-병풀 | B22: 월 운영비 = 전기비 + 수도비 + 재료비 + 인건비 + 기기 대여비 + 기타비용 | C22: ='비용구성'!D10 | D22: ='비용구성'!E10+'비용구성'!G10+'비용구성'!I10+'비용구성'!K10+'비용구성'!M10+'비용구성'!O10 | E22: =C22-D22 | F22: 0.5 | G22: =IF(ABS(E22)<=F22,"PASS","FAIL")
A23: S002-상추 | B23: 월 영업이익 = 공간 대여자 예상수익 + 사업장 영업이익 | C23: ='요약'!Y11 | D23: ='요약'!AA11+'요약'!AC11 | E23: =C23-D23 | F23: 0.5 | G23: =IF(ABS(E23)<=F23,"PASS","FAIL")
A24: S002-상추 | B24: 월 총 용수량 = 작물 순소비량 + 배액량 + 기타 용수량 | C24: ='요약'!R11 | D24: ='요약'!O11+'요약'!P11+'요약'!Q11 | E24: =C24-D24 | F24: 0.001 | G24: =IF(ABS(E24)<=F24,"PASS","FAIL")
A25: S002-상추 | B25: 월 운영비 = 전기비 + 수도비 + 재료비 + 인건비 + 기기 대여비 + 기타비용 | C25: ='비용구성'!D11 | D25: ='비용구성'!E11+'비용구성'!G11+'비용구성'!I11+'비용구성'!K11+'비용구성'!M11+'비용구성'!O11 | E25: =C25-D25 | F25: 0.5 | G25: =IF(ABS(E25)<=F25,"PASS","FAIL")
A26: S002-딸기 | B26: 월 영업이익 = 공간 대여자 예상수익 + 사업장 영업이익 | C26: ='요약'!Y12 | D26: ='요약'!AA12+'요약'!AC12 | E26: =C26-D26 | F26: 0.5 | G26: =IF(ABS(E26)<=F26,"PASS","FAIL")
A27: S002-딸기 | B27: 월 총 용수량 = 작물 순소비량 + 배액량 + 기타 용수량 | C27: ='요약'!R12 | D27: ='요약'!O12+'요약'!P12+'요약'!Q12 | E27: =C27-D27 | F27: 0.001 | G27: =IF(ABS(E27)<=F27,"PASS","FAIL")
A28: S002-딸기 | B28: 월 운영비 = 전기비 + 수도비 + 재료비 + 인건비 + 기기 대여비 + 기타비용 | C28: ='비용구성'!D12 | D28: ='비용구성'!E12+'비용구성'!G12+'비용구성'!I12+'비용구성'!K12+'비용구성'!M12+'비용구성'!O12 | E28: =C28-D28 | F28: 0.5 | G28: =IF(ABS(E28)<=F28,"PASS","FAIL")
A29: S002-바질 | B29: 월 영업이익 = 공간 대여자 예상수익 + 사업장 영업이익 | C29: ='요약'!Y13 | D29: ='요약'!AA13+'요약'!AC13 | E29: =C29-D29 | F29: 0.5 | G29: =IF(ABS(E29)<=F29,"PASS","FAIL")
A30: S002-바질 | B30: 월 총 용수량 = 작물 순소비량 + 배액량 + 기타 용수량 | C30: ='요약'!R13 | D30: ='요약'!O13+'요약'!P13+'요약'!Q13 | E30: =C30-D30 | F30: 0.001 | G30: =IF(ABS(E30)<=F30,"PASS","FAIL")
A31: S002-바질 | B31: 월 운영비 = 전기비 + 수도비 + 재료비 + 인건비 + 기기 대여비 + 기타비용 | C31: ='비용구성'!D13 | D31: ='비용구성'!E13+'비용구성'!G13+'비용구성'!I13+'비용구성'!K13+'비용구성'!M13+'비용구성'!O13 | E31: =C31-D31 | F31: 0.5 | G31: =IF(ABS(E31)<=F31,"PASS","FAIL")
A32: S002-애플민트 | B32: 월 영업이익 = 공간 대여자 예상수익 + 사업장 영업이익 | C32: ='요약'!Y14 | D32: ='요약'!AA14+'요약'!AC14 | E32: =C32-D32 | F32: 0.5 | G32: =IF(ABS(E32)<=F32,"PASS","FAIL")
A33: S002-애플민트 | B33: 월 총 용수량 = 작물 순소비량 + 배액량 + 기타 용수량 | C33: ='요약'!R14 | D33: ='요약'!O14+'요약'!P14+'요약'!Q14 | E33: =C33-D33 | F33: 0.001 | G33: =IF(ABS(E33)<=F33,"PASS","FAIL")
A34: S002-애플민트 | B34: 월 운영비 = 전기비 + 수도비 + 재료비 + 인건비 + 기기 대여비 + 기타비용 | C34: ='비용구성'!D14 | D34: ='비용구성'!E14+'비용구성'!G14+'비용구성'!I14+'비용구성'!K14+'비용구성'!M14+'비용구성'!O14 | E34: =C34-D34 | F34: 0.5 | G34: =IF(ABS(E34)<=F34,"PASS","FAIL")
A35: S002-쪽파 | B35: 월 영업이익 = 공간 대여자 예상수익 + 사업장 영업이익 | C35: ='요약'!Y15 | D35: ='요약'!AA15+'요약'!AC15 | E35: =C35-D35 | F35: 0.5 | G35: =IF(ABS(E35)<=F35,"PASS","FAIL")
A36: S002-쪽파 | B36: 월 총 용수량 = 작물 순소비량 + 배액량 + 기타 용수량 | C36: ='요약'!R15 | D36: ='요약'!O15+'요약'!P15+'요약'!Q15 | E36: =C36-D36 | F36: 0.001 | G36: =IF(ABS(E36)<=F36,"PASS","FAIL")
A37: S002-쪽파 | B37: 월 운영비 = 전기비 + 수도비 + 재료비 + 인건비 + 기기 대여비 + 기타비용 | C37: ='비용구성'!D15 | D37: ='비용구성'!E15+'비용구성'!G15+'비용구성'!I15+'비용구성'!K15+'비용구성'!M15+'비용구성'!O15 | E37: =C37-D37 | F37: 0.5 | G37: =IF(ABS(E37)<=F37,"PASS","FAIL")
A38: S002-병풀 | B38: 월 영업이익 = 공간 대여자 예상수익 + 사업장 영업이익 | C38: ='요약'!Y16 | D38: ='요약'!AA16+'요약'!AC16 | E38: =C38-D38 | F38: 0.5 | G38: =IF(ABS(E38)<=F38,"PASS","FAIL")
A39: S002-병풀 | B39: 월 총 용수량 = 작물 순소비량 + 배액량 + 기타 용수량 | C39: ='요약'!R16 | D39: ='요약'!O16+'요약'!P16+'요약'!Q16 | E39: =C39-D39 | F39: 0.001 | G39: =IF(ABS(E39)<=F39,"PASS","FAIL")
A40: S002-병풀 | B40: 월 운영비 = 전기비 + 수도비 + 재료비 + 인건비 + 기기 대여비 + 기타비용 | C40: ='비용구성'!D16 | D40: ='비용구성'!E16+'비용구성'!G16+'비용구성'!I16+'비용구성'!K16+'비용구성'!M16+'비용구성'!O16 | E40: =C40-D40 | F40: 0.5 | G40: =IF(ABS(E40)<=F40,"PASS","FAIL")
A41: S003-상추 | B41: 월 영업이익 = 공간 대여자 예상수익 + 사업장 영업이익 | C41: ='요약'!Y17 | D41: ='요약'!AA17+'요약'!AC17 | E41: =C41-D41 | F41: 0.5 | G41: =IF(ABS(E41)<=F41,"PASS","FAIL")
...
